Workbook

Sheet Total Price
A1: Item NO. | B1: Item | C1: Price | D1: Quantity | E1: Total | G1: Item NO. | H1: Item | I1: Price | J1: Total
A2: 1 | B2: Actuator | C2: ='Cycloidal Gearbox'!I28 -> 83.953942 | D2: 12 | E2: =C2*D2 -> 1007.4473 | G2: 1 | H2: Actuator | I2: ='Cycloidal Gearbox'!I28 -> 83.953942 | J2: ='Cycloidal Gearbox'!L28 -> 202.56345
A3: 2 | B3: Leg Assembly | C3: ='Leg Assembly'!I24 -> 45.291522 | D3: 12 | E3: =C3*D3 -> 543.49826 | G3: 2 | H3: Leg Assembly | I3: ='Leg Assembly'!I24 -> 45.291522 | J3: ='Leg Assembly'!L24 -> 163.71479
A4: 3 | B4: FOC Drive Board | C4: ='FOC PCB'!I41 -> 38.513933 | D4: 12 | E4: =C4*D4 -> 462.1672 | G4: 3 | H4: FOC Drive Board | I4: ='FOC PCB'!I41 -> 38.513933 | J4: ='FOC PCB'!L41 -> 224.2238
A5: 4 | B5: Raspberry Pi Pico | C5: 8 | D5: 1 | E5: =C5*D5 -> 8 | G5: 4 | H5: Raspberry Pi Pico | I5: 8 | J5: =1*I5 -> 8
A6: 5 | B6: 3D Printer Filament | C6: 15 | D6: 4 | E6: =C6*D6 -> 60 | G6: 5
A7: 6 | B7: Body Assembly | C7: ='Body Assembly'!L12 -> 489.98436 | D7: 1 | E7: =C7*D7 -> 489.98436 | G7: 6
A8: Total Project Cost: | E8: =SUM(E2:E7) -> 2571.0971 | G8: Additional Funding Needed: | J8: =SUM(J2:J6) -> 598.50204
A15: Funding Money
A16: Who | C16: Amount
A17: Chad Robinson | C17: 250

Sheet Body Assembly
A1: ITEM NO. | B1: PART NUMBER | C1: DESCRIPTION | D1: Web Link for Purchasing | E1: Cost per Time Purchased($) | F1: Quantity Per Time Purchased (pcs & kg) | G1: Part Unit Cost Per Purcahse($) | H1: QTY. | I1: Cost per Assembly | J1: Units In Stock | K1: Units Needed For Complete Quadruped | L1: Extra Cost Needed For Complete Quadruped
A2: 1 | B2: Printed Body Part | C2: All printed body parts including center body, shoulder-chest, and hip supporting panels printed with PLA | D2: https://a.co/d/0axj8nc5 | E2: 26.98 | F2: 2 | G2: =E2*0.741/F2 -> 9.99609 | H2: 2 | I2: =G2*H2 -> 19.99218 | J2: 0 | K2: 2 | L2: =I2*K2 -> 39.98436
A3: 2
A4: 3
A5: 4
A6: 5
A7: 6 | B7: 600MM Length Carbon Fiber Tube | C7: Carbon Fiber Rods | D7: https://a.co/d/098f3vCr | E7: 25 | F7: 2 | G7: =E7/F7 -> 12.5 | H7: 2 | I7: =G7*H7 -> 25 | J7: 0 | K7: 4 | L7: =K7*G7 -> 50
A8: 7
A9: 8
A10: 9
A11: 10 | L11: 400
A12: Total Cost Per Assembly($): | I12: =SUM(I2:I10) -> 44.99218 | J12: Extra Cost Needed For Complete Quadruped($): | L12: =SUM(L2:L11) -> 489.98436

Sheet Cycloidal Gearbox
A1: ITEM NO. | B1: PART NUMBER | C1: DESCRIPTION | D1: Web Link for Purchasing | E1: Cost per Time Purchased($) | F1: Quantity Per Time Purchased (pcs & kg) | G1: Part Unit Cost Per Purcahse($) | H1: QTY. | I1: Cost per Assembly | J1: Units In Stock | K1: Units Needed For Complete Quadruped | L1: Extra Cost Needed For Complete Quadruped
A2: 1 | B2: Ring Gear | C2: PLA Filament | D2: https://a.co/d/0gjZemYR | E2: 29.98 | F2: 0.0301 | G2: 0.451 | H2: 1 | I2: 0.451199 | J2: 1 | K2: 12 | L2: =(IF(K2-J2<0,0,K2-J2))*G2 -> 4.961
A3: 2 | B3: Opposite Ring Gear | F3: 0.0301 | G3: 0.451 | H3: 1 | I3: 0.451199 | J3: 1 | K3: 12 | L3: =(IF(K3-J3<0,0,K3-J3))*G3 -> 4.961
A4: 3 | B4: Cycloidal Gear | F4: 0.0115 | G4: 0.172 | H4: 2 | I4: 0.3444702 | J4: 2 | K4: 24 | L4: =(IF(K4-J4<0,0,K4-J4))*G4 -> 3.784
A5: 4 | B5: Input Shaft | F5: 0.0036 | G5: 0.054 | H5: 1 | I5: 0.0535143 | J5: 1 | K5: 12 | L5: =(IF(K5-J5<0,0,K5-J5))*G5 -> 0.594
A6: 5 | B6: Spacer Washer | F6: 0.0002 | G6: 0.002 | H6: 1 | I6: 0.0023984 | J6: 1 | K6: 12 | L6: =(IF(K6-J6<0,0,K6-J6))*G6 -> 0.022
A7: 6 | B7: Bearing Spacer Big | F7: 0.0004 | G7: 0.006 | H7: 1 | I7: 0.0055463 | J7: 1 | K7: 12 | L7: =(IF(K7-J7<0,0,K7-J7))*G7 -> 0.066
A8: 7 | B8: "HM155kV Motor Mount V2" | F8: 0.0422 | G8: 0.633 | H8: 1 | I8: 0.6327279 | J8: 1 | K8: 12 | L8: =(IF(K8-J8<0,0,K8-J8))*G8 -> 6.963
A9: 8 | B9: Encoder Magnent Mount | F9: 0.0005 | G9: 0.007 | H9: 1 | I9: 0.0068954 | J9: 1 | K9: 12 | L9: =(IF(K9-J9<0,0,K9-J9))*G9 -> 0.077
A10: 9 | B10: Shaft Coupler for HM155KV | F10: 0.0032 | G10: 0.049 | H10: 1 | I10: 0.0485676 | J10: 1 | K10: 12 | L10: =(IF(K10-J10<0,0,K10-J10))*G10 -> 0.539
A11: 10 | B11: FOC Board Spacer | F11: 0.0001 | G11: 0.002 | H11: 4 | I11: 0.0077948 | J11: 4 | K11: 48 | L11: =(IF(K11-J11<0,0,K11-J11))*G11 -> 0.088
A12: 11 | B12: V3 Output Shaft Opposite | F12: 0.0125 | G12: 0.188 | H12: 1 | I12: 0.1876748 | J12: 1 | K12: 12 | L12: =(IF(K12-J12<0,0,K12-J12))*G12 -> 2.068
A13: 12 | B13: V2 Output Shaft | F13: 0.0195 | G13: 0.293 | H13: 1 | I13: 0.2926048 | J13: 1 | K13: 12 | L13: =(IF(K13-J13<0,0,K13-J13))*G13 -> 3.223
A14: 13 | B14: "50mm*65mm*7mm Ball Bearing" | C14: Bearing For both Ring Gears | D14: https://a.co/d/0iJVO1oG | E14: 28.09 | F14: 10 | G14: =E14/F14 -> 2.809 | H14: 2 | I14: =G14*H14 -> 5.618 | J14: 5 | K14: 24 | L14: =(IF(K14-J14<0,0,K14-J14))*G14 -> 53.371
A15: 14 | B15: "M3*0.5 BY 25mm Socket Head Screw" | C15: Screw to secure two Ring Gears together | D15: https://a.co/d/0gNaFcET | E15: 8.39 | F15: 50 | G15: =E15/F15 -> 0.1678 | H15: 6 | I15: =G15*H15 -> 1.0068 | J15: 20 | K15: 72 | L15: =(IF(K15-J15<0,0,K15-J15))*G15 -> 8.7256
A16: 15 | B16: 15mm by 24mm by 5mm Ball Bearing | C16: Beaing for Cycloidal Gear | D16: https://a.co/d/02tsqvkJ | E16: 9.59 | F16: 10 | G16: =E16/F16 -> 0.959 | H16: 1 | I16: =G16*H16 -> 0.959 | J16: 4 | K16: 12 | L16: =(IF(K16-J16<0,0,K16-J16))*G16 -> 7.672
A17: 16 | B17: M3 by 8mm Button Head Cap Screw | C17: Screw for both Motor Mount and Motor Coupler connection | D17: https://a.co/d/02je179N | E17: 5.99 | F17: 50 | G17: =E17/F17 -> 0.1198 | H17: 6 | I17: =G17*H17 -> 0.7188 | J17: 0 | K17: 72 | L17: =(IF(K17-J17<0,0,K17-J17))*G17 -> 8.6256
A18: 17 | B18: M4 by 8mm Button Head Cap Screw | C18: Screw to secure the HM155kv onto Motor Mount | D18: https://a.co/d/0fTSP7Vz | E18: 7.99 | F18: 50 | G18: =E18/F18 -> 0.1598 | H18: 4 | I18: =G18*H18 -> 0.6392 | J18: 22 | K18: 48 | L18: =(IF(K18-J18<0,0,K18-J18))*G18 -> 4.1548
A19: 18 | B19: M3 by 2.4mm Hex Nut | C19: Nut to secure the FOC Board | D19: https://a.co/d/09MJXPxa | E19: 5.49 | F19: 200 | G19: =E19/F19 -> 0.02745 | H19: 8 | I19: =G19*H19 -> 0.2196 | J19: 25 | K19: 48 | L19: =(IF(K19-J19<0,0,K19-J19))*G19 -> 0.63135
A20: 19 | B20: HM-6208 motor | C20: Electric Motor | D20: https://www.hobbywingdirect.com/products/xrotor-m-6208-motor-ul | E20: 60 | F20: 1 | G20: =E20/F20 -> 60 | H20: 1 | I20: =G20*H20 -> 60 | J20: 12 | K20: 12 | L20: =(IF(K20-J20<0,0,K20-J20))*G20 -> 0
A21: 20 | B21: 22mm*10mm*6mm Ball Bearing | C21: Bearing to secure the Input Shaft | D21: https://a.co/d/02soELBD | E21: 8.29 | F21: 8 | G21: =E21/F21 -> 1.03625 | H21: 1 | I21: =G21*H21 -> 1.03625 | J21: 6 | K21: 12 | L21: =(IF(K21-J21<0,0,K21-J21))*G21 -> 6.2175
A22: 21 | B22: M2.5 by 25mm Socket Head Screw | C22: Screw to secure and strengthen the Ouput Shaft | D22: https://a.co/d/09MJXPxa | E22: 8.28 | F22: 100 | G22: =E22/F22 -> 0.0828 | H22: 6 | I22: =G22*H22 -> 0.4968 | J22: 15 | K22: 72 | L22: =(IF(K22-J22<0,0,K22-J22))*G22 -> 4.7196
A23: 22 | B23: 8mm*10mm*12mm Sleeve Bearing | C23: Bearing to be used at the contact of Cycloidal Gear and the Output Shaft | D23: https://a.co/d/0ckISucZ | E23: 7.19 | F23: 8 | G23: =E23/F23 -> 0.89875 | H23: 6 | I23: =G23*H23 -> 5.3925 | J23: 24 | K23: 72 | L23: =(IF(K23-J23<0,0,K23-J23))*G23 -> 43.14
A24: 23 | B24: 25mm*37mm*7mm Bearing | C24: Bearing to secure the Motor Coupler and the Input Shaft on the Output Shaft | D24: https://a.co/d/0cG1vUeo | E24: 13.19 | F24: 10 | G24: =E24/F24 -> 1.319 | H24: 1 | I24: =G24*H24 -> 1.319 | J24: 9 | K24: 12 | L24: =(IF(K24-J24<0,0,K24-J24))*G24 -> 3.957
A25: 24 | B25: M3 by 5mm by 6mm Heat Insert | C25: Heat Insert Nut for screw connection | D25: https://a.co/d/04sPH867 | E25: 9.19 | F25: 100 | G25: =E25/F25 -> 0.0919 | H25: 30 | I25: =G25*H25 -> 2.757 | J25: 18 | K25: 360 | L25: =(IF(K25-J25<0,0,K25-J25))*G25 -> 31.4298
... A27: 26 | B27: Encoder Magnent | C27: Used on Encoder Magnent Mount for Position Feedback | D27: https://a.co/d/0dExNett | E27: 15.1 | F27: 20 | G27: =E27/F27 -> 0.755 | H27: 1 | I27: =G27*H27 -> 0.755 | J27: 15 | K27: 0 | L27: =(IF(K27-J27<0,0,K27-J27))*G27 -> 0
A28: Total Cost Per Assembly($): | I28: =SUM(I2:I27) -> 83.953942 | J28: Extra Cost Needed For Complete Quadruped($): | L28: =SUM(L2:L27) -> 202.56345

Sheet FOC PCB
A1: ITEM NO. | B1: PART NUMBER | C1: DESCRIPTION | D1: Web Link for Purchasing | E1: Cost per Time Purchased($) | F1: Quantity Per Time Purchased (pcs & kg) | G1: Part Unit Cost Per Purcahse($) | H1: QTY. | I1: Cost per Assembly | J1: "Units In Stock (Non-repetitive)" | K1: Units Needed For Complete Quadruped | L1: Extra Cost Needed For Complete Quadruped
A2: 1 | B2: PCB BOARD | C2: Printed Circuit Board | D2: JLCPCB | E2: 34.97 | F2: 5 | G2: =E2/F2 -> 6.994 | H2: 1 | I2: =G2*H2 -> 6.994 | J2: 5 | K2: 12 | L2: =(IF(K2-J2<0,0,K2-J2))*G2 -> 48.958
A3: 2 | B3: STM32G431CBU6 | C3: Main Processor | D3: Mouser | E3: 30.36 | F3: 6 | G3: =E3/F3 -> 5.06 | H3: 1 | I3: =G3*H3 -> 5.06 | J3: 6 | K3: 12 | L3: =(IF(K3-J3<0,0,K3-J3))*G3 -> 30.36
A4: 3 | B4: Capacitor 0.1 uF 25V 0402 | C4: CL05A104KA5NNNC | D4: Digikey | E4: 0.36 | F4: 180 | G4: =E4/F4 -> 0.002 | H4: =F4/12 -> 15 | I4: =G4*H4 -> 0.03 | J4: 180 | K4: 180 | L4: =(IF(K4-J4<0,0,K4-J4))*G4 -> 0
A5: 4 | B5: Capacitor 10 uF 35V 0805 | C5: GRM21BC8YA106ME11L | D5: Digikey | E5: 5.88 | F5: 50 | G5: =E5/F5 -> 0.1176 | H5: =48/12 -> 4 | I5: =G5*H5 -> 0.4704 | J5: 50 | K5: 48 | L5: =(IF(K5-J5<0,0,K5-J5))*G5 -> 0
A6: 5 | B6: Resistor 22 Ohm 0402 | C6: RC0402FR-0722RL | D6: Digikey | E6: 0.45 | F6: 72 | G6: =E6/F6 -> 0.00625 | H6: =F6/12 -> 6 | I6: =G6*H6 -> 0.0375 | J6: 72 | K6: 72 | L6: =(IF(K6-J6<0,0,K6-J6))*G6 -> 0
A7: 6 | B7: Capacitor 1 uF 25V 0402 | C7: CL05A105KA5NQNC | D7: DigiKey | E7: 0.76 | F7: 36 | G7: =E7/F7 -> 0.021111111 | H7: =F7/12 -> 3 | I7: =G7*H7 -> 0.063333333 | J7: 36 | K7: 36 | L7: =(IF(K7-J7<0,0,K7-J7))*G7 -> 0
A8: 7 | B8: Capacitor 10 uF 10V 0402 | C8: CL05A106MP5NUNC | D8: Digikey | E8: 0.65 | F8: 24 | G8: =E8/F8 -> 0.027083333 | H8: =F8/12 -> 2 | I8: =G8*H8 -> 0.054166667 | J8: 24 | K8: 24 | L8: =(IF(K8-J8<0,0,K8-J8))*G8 -> 0
A9: 8 | B9: Capacitor 1000 pF 50V 0402 | C9: GRM155R71H102KA01D | D9: DigiKey | E9: 0.04 | F9: 12 | G9: =E9/F9 -> 0.0033333333 | H9: =F9/12 -> 1 | I9: =G9*H9 -> 0.0033333333 | J9: 12 | K9: 12 | L9: =(IF(K9-J9<0,0,K9-J9))*G9 -> 0
A10: 9 | B10: Capacitor 10 uF 35V 0402 | C10: GRM188R6YA106MA73D | D10: Digikey | E10: 1.61 | F10: 12 | G10: =E10/F10 -> 0.13416667 | H10: =F10/12 -> 1 | I10: =G10*H10 -> 0.13416667 | J10: 12 | K10: 12 | L10: =(IF(K10-J10<0,0,K10-J10))*G10 -> 0
A11: 10 | B11: Capacitor 100 pF 50V 0603 | C11: GRM1885C1H101JA01D | D11: DigiKey | E11: 0.17 | F11: 12 | G11: =E11/F11 -> 0.014166667 | H11: =F11/12 -> 1 | I11: =G11*H11 -> 0.014166667 | J11: 12 | K11: 12 | L11: =(IF(K11-J11<0,0,K11-J11))*G11 -> 0
A12: 11 | B12: Capactior 10 uF 16V 0805 | C12: CL21B106KOQNNNE | D12: Digikey | E12: 0.84 | F12: 24 | G12: =E12/F12 -> 0.035 | H12: =F12/12 -> 2 | I12: =G12*H12 -> 0.07 | J12: 24 | K12: 24 | L12: =(IF(K12-J12<0,0,K12-J12))*G12 -> 0
A13: 12 | B13: Diode Standard 75V SOD523F | C13: 1N4148WTCT-ND | D13: DigiKey | E13: 2.48 | F13: 36 | G13: =E13/F13 -> 0.068888889 | H13: =F13/12 -> 3 | I13: =G13*H13 -> 0.20666667 | J13: 36 | K13: 36 | L13: =(IF(K13-J13<0,0,K13-J13))*G13 -> 0
A14: 13 | B14: Diode Schottky 40V 1A STMITE | C14: STPS1L40M | D14: DigiKey | E14: 5.93 | F14: 24 | G14: =E14/F14 -> 0.24708333 | H14: =F14/12 -> 2 | I14: =G14*H14 -> 0.49416667 | J14: 24 | K14: 24 | L14: =(IF(K14-J14<0,0,K14-J14))*G14 -> 0
A15: 14 | B15: Resistor 10K Ohm 01005 | C15: PFR02S-103-JNH | D15: DigiKey | E15: 0.52 | F15: 25 | G15: =E15/F15 -> 0.0208 | H15: =24/12 -> 2 | I15: =G15*H15 -> 0.0416 | J15: 25 | K15: 24 | L15: =(IF(K15-J15<0,0,K15-J15))*G15 -> 0
A16: 15 | B16: Resistor 0 Ohm Jumper 01005 | C16: ERJ-XGN0R00Y | D16: DigiKey | E16: 0.83 | F16: 12 | G16: =E16/F16 -> 0.069166667 | H16: =F16/12 -> 1 | I16: =G16*H16 -> 0.069166667 | J16: 12 | K16: 12 | L16: =(IF(K16-J16<0,0,K16-J16))*G16 -> 0
A17: 16 | B17: Resistor 1M Ohm 0402 | C17: RC0402FR-071ML | D17: DigiKey | E17: 0.04 | F17: 12 | G17: =E17/F17 -> 0.0033333333 | H17: =F17/12 -> 1 | I17: =G17*H17 -> 0.0033333333 | J17: 12 | K17: 12 | L17: =(IF(K17-J17<0,0,K17-J17))*G17 -> 0
A18: 17 | B18: Resistor 1.5k Ohm 0402 | C18: RC0402FR-071K5L | D18: DigiKey | E18: 0.16 | F18: 50 | G18: =E18/F18 -> 0.0032 | H18: =48/12 -> 4 | I18: =G18*H18 -> 0.0128 | J18: 50 | K18: 48 | L18: =(IF(K18-J18<0,0,K18-J18))*G18 -> 0
A19: 18 | B19: Resistor 0 Ohm jumper 0402 | C19: RC0402FR-070RL | D19: DigiKey | E19: 0.24 | F19: 24 | G19: =E19/F19 -> 0.01 | H19: =F19/12 -> 2 | I19: =G19*H19 -> 0.02 | J19: 24 | K19: 24 | L19: =(IF(K19-J19<0,0,K19-J19))*G19 -> 0
A20: 19 | B20: Resistor 22k Ohm 0402 | C20: ERA-2AEB223X | D20: DigiKey | E20: 2.74 | F20: 36 | G20: =E20/F20 -> 0.076111111 | H20: =F20/12 -> 3 | I20: =G20*H20 -> 0.22833333 | J20: 36 | K20: 36 | L20: =(IF(K20-J20<0,0,K20-J20))*G20 -> 0
A21: 20 | B21: Resistor 1k Ohm 0402 | C21: RC0402JR-071KL | D21: DigiKey | E21: 0.05 | F21: 12 | G21: =E21/F21 -> 0.0041666667 | H21: =F21/12 -> 1 | I21: =G21*H21 -> 0.0041666667 | J21: 12 | K21: 12 | L21: =(IF(K21-J21<0,0,K21-J21))*G21 -> 0
A22: 21 | B22: Resistor 169k Ohm 0402 | C22: RC0402FR-07169KL | D22: DigiKey | E22: 0.05 | F22: 12 | G22: =E22/F22 -> 0.0041666667 | H22: =F22/12 -> 1 | I22: =G22*H22 -> 0.0041666667 | J22: 12 | K22: 12 | L22: =(IF(K22-J22<0,0,K22-J22))*G22 -> 0
A23: 22 | B23: Resistor 2.2k Ohm 0402 | C23: RMCF0402FT2K20 | D23: DigiKey | E23: 0.17 | F23: 36 | G23: =E23/F23 -> 0.0047222222 | H23: =F23/12 -> 3 | I23: =G23*H23 -> 0.014166667 | J23: 36 | K23: 36 | L23: =(IF(K23-J23<0,0,K23-J23))*G23 -> 0
A24: 23 | B24: Resistor 10k Ohm 0402 | C24: RC0402FR-0710KL | D24: DigiKey | E24: 0.23 | F24: 25 | G24: =E24/F24 -> 0.0092 | H24: =24/12 -> 2 | I24: =G24*H24 -> 0.0184 | J24: 25 | K24: 24 | L24: =(IF(K24-J24<0,0,K24-J24))*G24 -> 0
A25: 24 | B25: Resistor 4.7k Ohm 0402 | C25: RC0402JR-074K7L | D25: DigiKey | E25: 0.04 | F25: 12 | G25: =E25/F25 -> 0.0033333333 | H25: =F25/12 -> 1 | I25: =G25*H25 -> 0.0033333333 | J25: 12 | K25: 12 | L25: =(IF(K25-J25<0,0,K25-J25))*G25 -> 0
A26: 25 | B26: Resistor 18k Ohm 0402 | C26: RC0402FR-0718KL | D26: DigiKey | E26: 0.08 | F26: 12 | G26: =E26/F26 -> 0.0066666667 | H26: =F26/12 -> 1 | I26: =G26*H26 -> 0.0066666667 | J26: 12 | K26: 12 | L26: =(IF(K26-J26<0,0,K26-J26))*G26 -> 0
A27: 26 | B27: Resistor 14k Ohm 0402 | C27: RC0402FR-0714KL | D27: DigiKey | E27: 0.05 | F27: 12 | G27: =E27/F27 -> 0.0041666667 | H27: =F27/12 -> 1 | I27: =G27*H27 -> 0.0041666667 | J27: 12 | K27: 12 | L27: =(IF(K27-J27<0,0,K27-J27))*G27 -> 0
A28: 27 | B28: Resistor 1M Ohm 0603 | C28: RC0603FR-071ML | D28: DigiKey | E28: 0.11 | F28: 12 | G28: =E28/F28 -> 0.0091666667 | H28: =F28/12 -> 1 | I28: =G28*H28 -> 0.0091666667 | J28: 12 | K28: 12 | L28: =(IF(K28-J28<0,0,K28-J28))*G28 -> 0
A29: 28 | B29: Resistor 0.003 Ohm 2512 | C29: PA2512FKF070R003E | D29: Digikey | E29: 10.84 | F29: 36 | G29: =E29/F29 -> 0.30111111 | H29: =F29/12 -> 3 | I29: =G29*H29 -> 0.90333333 | J29: 36 | K29: 36 | L29: =(IF(K29-J29<0,0,K29-J29))*G29 -> 0
A30: 29 | B30: TVS Diode 24VWM 44VC SOT23-3 | C30: NUP2105LT1G | D30: Digikey | E30: 3.62 | F30: 24 | G30: =E30/F30 -> 0.15083333 | H30: =F30/12 -> 2 | I30: =G30*H30 -> 0.30166667 | J30: 24 | K30: 24 | L30: =(IF(K30-J30<0,0,K30-J30))*G30 -> 0
A31: 30 | B31: Capactior Aluminum 470 uF 35V | C31: EMZS350ARA471MHA0G | D31: Digikey | E31: 6.71 | F31: 12 | G31: =E31/F31 -> 0.55916667 | H31: =F31/12 -> 1 | I31: =G31*H31 -> 0.55916667 | J31: 12 | K31: 12 | L31: =(IF(K31-J31<0,0,K31-J31))*G31 -> 0
A32: 31 | B32: Mosfet N-Ch 80V 100A 8VSON | C32: CSD19502Q5B | D32: Digikey | E32: 59.67 | F32: 30 | G32: =E32/F32 -> 1.989 | H32: =F32/5 -> 6 | I32: =G32*H32 -> 11.934 | J32: 30 | K32: 72 | L32: =(IF(K32-J32<0,0,K32-J32))*G32 -> 83.538
A33: 32 | B33: Terminator | C33: 39-30-1042 | D33: Mouser | E33: 13.1 | F33: 5 | G33: =E33/F33 -> 2.62 | H33: =F33/5 -> 1 | I33: =G33*H33 -> 2.62 | J33: 5 | K33: 12 | L33: =(IF(K33-J33<0,0,K33-J33))*G33 -> 18.34
A34: 33 | B34: ME3116 | C34: SOT95P270X145-6N_ME3116 | D34: LCSC | E34: 1.372 | F34: 10 | G34: =E34/F34 -> 0.1372 | H34: 1 | I34: =G34*H34 -> 0.1372 | J34: 10 | K34: 12 | L34: =(IF(K34-J34<0,0,K34-J34))*G34 -> 0.2744
A35: 34 | B35: ME6211C30M5 | C35: SOT-23-5 | D35: LCSC | E35: 0.637 | F35: 10 | G35: =E35/F35 -> 0.0637 | H35: 1 | I35: =G35*H35 -> 0.0637 | J35: 10 | K35: 12 | L35: =(IF(K35-J35<0,0,K35-J35))*G35 -> 0.1274
A36: 35 | B36: SPX3819M5-L-5-0 | C36: SOT-23-5 | D36: LCSC | E36: 2.017 | F36: 10 | G36: =E36/F36 -> 0.2017 | H36: 1 | I36: =G36*H36 -> 0.2017 | J36: 10 | K36: 12 | L36: =(IF(K36-J36<0,0,K36-J36))*G36 -> 0.4034
A37: 36 | B37: SOIC127P600X175-8N_CAN | C37: CAN Bus Chip | D37: Mouser | E37: 16.9 | F37: 10 | G37: =E37/F37 -> 1.69 | H37: 1 | I37: =G37*H37 -> 1.69 | J37: 15 | K37: 12 | L37: =(IF(K37-J37<0,0,K37-J37))*G37 -> 0
A38: 37 | B38: Trimmer Potentiometer | C38: N/A | D38: Mouser | E38: 15.8 | F38: 10 | G38: =E38/F38 -> 1.58 | H38: 1 | I38: =G38*H38 -> 1.58 | J38: 5 | K38: 12 | L38: =(IF(K38-J38<0,0,K38-J38))*G38 -> 11.06
A39: 38 | B39: Magnetic Encoder | C39: AS5600 | D39: Mouser | E39: 38 | F39: 10 | G39: =E39/F39 -> 3.8 | H39: 1 | I39: =G39*H39 -> 3.8 | J39: 5 | K39: 12 | L39: =(IF(K39-J39<0,0,K39-J39))*G39 -> 26.6
A40: 39 | B40: QFN50P400X400X90-25N-D_Gatedriver1 | C40: FD6288Q | D40: LCSC | E40: 6.518 | F40: 10 | G40: =E40/F40 -> 0.6518 | H40: 1 | I40: =G40*H40 -> 0.6518 | J40: 5 | K40: 12 | L40: =(IF(K40-J40<0,0,K40-J40))*G40 -> 4.5626
...

Sheet Leg Assembly
A1: ITEM NO. | B1: PART NUMBER | C1: DESCRIPTION | D1: Web Link for Purchasing | E1: "Cost per Time Purchased($)" | F1: "Quantity Per Time Purchased (pcs & kg)" | G1: "Part Unit Cost Per Purcahse($)" | H1: QTY. | I1: "Cost per Assembly" | J1: "Units In Stock (Non-repetitive)" | K1: Units Needed For Complete Quadruped | L1: Extra Cost Needed For Complete Quadruped
A2: 1 | B2: "Quadruped Thigh outer" | C2: 3D printed PLA | D2: https://a.co/d/0gjZemYR | E2: 29.98 | F2: 0.1845 | G2: =F2*E2/2 -> 2.765655 | H2: 1 | I2: =H2*G2 -> 2.765655 | J2: 0 | K2: =H2*4 -> 4 | L2: =(IF(K2-J2<0,0,K2-J2))*G2 -> 11.06262
A3: 2 | B3: "Quadruped Thigh inner" | F3: 0.1735 | G3: =F3*E$2/2 -> 2.600765 | H3: 1 | I3: =H3*G3 -> 2.600765 | J3: 0 | K3: =H3*4 -> 4 | L3: =(IF(K3-J3<0,0,K3-J3))*G3 -> 10.40306
A4: 3 | B4: "Quadruped Thigh Linkage" | F4: 0.0199 | G4: =F4*E$2/2 -> 0.298301 | H4: 1 | I4: =H4*G4 -> 0.298301 | J4: 0 | K4: =H4*4 -> 4 | L4: =(IF(K4-J4<0,0,K4-J4))*G4 -> 1.193204
A5: 4 | B5: "Quadruped Leg linkage" | F5: 0.0654 | G5: =F5*E$2/2 -> 0.980346 | H5: 1 | I5: =H5*G5 -> 0.980346 | J5: 0 | K5: =H5*4 -> 4 | L5: =(IF(K5-J5<0,0,K5-J5))*G5 -> 3.921384
A6: 5 | B6: "Quadruped Small Leg whole" | F6: 0.1858 | G6: =F6*E$2/2 -> 2.785142 | H6: 1 | I6: =H6*G6 -> 2.785142 | J6: 0 | K6: =H6*4 -> 4 | L6: =(IF(K6-J6<0,0,K6-J6))*G6 -> 11.140568
A7: 16 | B7: "Actuator back cover for quadruped" | F7: 0.0593 | G7: =F7*E$2/2 -> 0.888907 | H7: 1 | I7: =H7*G7 -> 0.888907 | J7: 0 | K7: =H7*4 -> 4 | L7: =(IF(K7-J7<0,0,K7-J7))*G7 -> 3.555628
A8: 17 | B8: "Quadruped Hip Bracket" | F8: 0.122 | G8: =F8*E$2/2 -> 1.82878 | H8: 1 | I8: =H8*G8 -> 1.82878 | J8: 0 | K8: =H8*4 -> 4 | L8: =(IF(K8-J8<0,0,K8-J8))*G8 -> 7.31512
A9: 18 | B9: Actuator back cover | F9: 0.0437 | G9: =F9*E$2/2 -> 0.655063 | H9: 2 | I9: =H9*G9 -> 1.310126 | J9: 0 | K9: =H9*4 -> 8 | L9: =(IF(K9-J9<0,0,K9-J9))*G9 -> 5.240504
A10: 20 | B10: Quadruped Foot | C10: 3D Printed TPU | D10: https://a.co/d/0dviCzEQ | E10: 8.99 | F10: 0.0388 | G10: 1.394 | H10: 1 | I10: =H10*G10 -> 1.394 | J10: 0 | K10: =H10*4 -> 4 | L10: =(IF(K10-J10<0,0,K10-J10))*G10 -> 5.576
A11: 19 | B11: "50*65*7MM BALL BEARING" | C11: Bearing for the Actuator Cover for Quadruped | D11: https://a.co/d/0iJVO1oG | E11: 28.09 | F11: 10 | G11: 2.809 | H11: 3 | I11: =H11*G11 -> 8.427 | J11: 0 | K11: =H11*4 -> 12 | L11: =(IF(K11-J11<0,0,K11-J11))*G11 -> 33.708
A12: 21 | B12: M3*6*5 insert | C12: Heat Insert Nut for screw connection | D12: https://a.co/d/02RLsYz4 | E12: 9.19 | F12: 100 | G12: 0.092 | H12: 12 | I12: =H12*G12 -> 1.104 | J12: 0 | K12: =H12*4 -> 48 | L12: =(IF(K12-J12<0,0,K12-J12))*G12 -> 4.416
A13: 22 | B13: M4*0.7*25mm Shoulder Screw | C13: For Small Leg Linkage Connection | D13: https://a.co/d/09Na5hOE | E13: 2.48 | F13: 5 | G13: 0.496 | H13: 2 | I13: =H13*G13 -> 0.992 | J13: 9 | K13: =H13*4 -> 8 | L13: =(IF(K13-J13<0,0,K13-J13))*G13 -> 0
A14: 23 | B14: M3*0.5*2.5mm Hex Nut | C14: For Foot Connection | D14: https://a.co/d/09gTfF0x | E14: 5.99 | F14: 200 | G14: =E14/F14 -> 0.02995 | H14: 24 | I14: =H14*G14 -> 0.7188 | J14: 0 | K14: =H14*4 -> 96 | L14: =(IF(K14-J14<0,0,K14-J14))*G14 -> 2.8752
A15: 6 | B15: M4*0.7*55mm Countersunk Screw | C15: For Thigh Connection | D15: https://a.co/d/0ifwolvi | E15: 6.99 | F15: 10 | G15: 0.699 | H15: 7 | I15: =H15*G15 -> 4.893 | J15: 0 | K15: =H15*4 -> 28 | L15: =(IF(K15-J15<0,0,K15-J15))*G15 -> 19.572
A16: 7 | B16: "M4*4*6mm heat insert" | C16: Heat Insert Nut For Screw Connection | D16: https://a.co/d/09anQYCh | E16: 7.29 | F16: 50 | G16: 0.146 | H16: 7 | I16: =H16*G16 -> 1.022 | J16: 19 | K16: =H16*4 -> 28 | L16: =(IF(K16-J16<0,0,K16-J16))*G16 -> 1.314
A17: 8 | B17: M3*12mm Button Head Cap Screw | C17: Screw For Most Gear Box-Motor Housing Connection | D17: https://a.co/d/005UyY34 | E17: 8.19 | F17: 100 | G17: =E17/F17 -> 0.0819 | H17: 24 | I17: =H17*G17 -> 1.9656 | J17: 0 | K17: =H17*4 -> 96 | L17: =(IF(K17-J17<0,0,K17-J17))*G17 -> 7.8624
A18: 9 | B18: 5*8*6mm sleeve | C18: Sleeve Bearing Support for Leg Linkage Pin connection | D18: https://a.co/d/05sPvYRi | E18: 12.79 | F18: 40 | G18: 0.32 | H18: 7 | I18: =H18*G18 -> 2.24 | J18: 0 | K18: =H18*4 -> 28 | L18: =(IF(K18-J18<0,0,K18-J18))*G18 -> 8.96
A19: 10 | B19: "6*19*2 thrust bearing with washer" | C19: Thrust Bearing Support for Linkage mechanism | D19: https://a.co/d/0bDdVhIm | E19: 8.29 | F19: 10 | G19: 0.829 | H19: 5 | I19: =H19*G19 -> 4.145 | J19: 8 | K19: =H19*4 -> 20 | L19: =(IF(K19-J19<0,0,K19-J19))*G19 -> 9.948
A20: 11 | B20: M4*0.7*45mm Shoulder Screw | C20: For Thigh-Small Leg Connection | D20: https://a.co/d/08z1tbBh | E20: 8.69 | F20: 8 | G20: =E20/F20 -> 1.08625 | H20: 1 | I20: =H20*G20 -> 1.08625 | J20: 0 | K20: =H20*4 -> 4 | L20: =(IF(K20-J20<0,0,K20-J20))*G20 -> 4.345
A21: 12 | B21: M4*0.7*3.2mm Hex Nut | C21: Hex Nut For Most Shoulder Bolt Connection | D21: https://a.co/d/03sRPgfF | E21: 6.29 | F21: 100 | G21: =E21/F21 -> 0.0629 | H21: 3 | I21: =H21*G21 -> 0.1887 | J21: 40 | K21: =H21*4 -> 12 | L21: =(IF(K21-J21<0,0,K21-J21))*G21 -> 0
A22: 14 | B22: 5*8*10mm sleeve | C22: Sleeve Bearing Support for Linkage Pin connection | D22: https://a.co/d/05cPeEqb | E22: 13.29 | F22: 40 | G22: =E22/F22 -> 0.33225 | H22: 3 | I22: =H22*G22 -> 0.99675 | J22: 10 | K22: =H22*4 -> 12 | L22: =(IF(K22-J22<0,0,K22-J22))*G22 -> 0.6645
A23: 15 | B23: M3*16mm Socket Head Cap Screw | C23: Screw For Most Actuattor-Leg Components Connection | D23: https://a.co/d/09MrIxQw | E23: 7.39 | F23: 50 | G23: =E23/F23 -> 0.1478 | H23: 18 | I23: =H23*G23 -> 2.6604 | J23: 0 | K23: =H23*4 -> 72 | L23: =(IF(K23-J23<0,0,K23-J23))*G23 -> 10.6416
A24: Total Cost Per Assembly($): | I24: =SUM(I2:I23) -> 45.291522 | J24: Extra Cost Needed For Complete Quadruped($): | L24: =SUM(L2:L23) -> 163.71479
